Rasa process starting
Added 'nlp_spacy' to component cache. Key 'nlp_spacy-en'.
Rasa Core server is up and running on http://localhost:5005
Failed to run custom action 'action_get_information'. Couldn't connect to the server at 'http://localhost:5055/webhook'. Is the server running? Error: HTTPConnectionPool(host='localhost', port=5055): Max retries exceeded with url: /webhook (Caused by NewConnectionError('<urllib3.connection.HTTPConnection object at 0x7f62706c8208>: Failed to establish a new connection: [Errno 111] Connection refused',))
Encountered an exception while running action 'action_get_information'. Bot will continue, but the actions events are lost. Make sure to fix the exception in your custom code.
Failed to run custom action 'action_get_information'. Couldn't connect to the server at 'http://localhost:5055/webhook'. Is the server running? Error: HTTPConnectionPool(host='localhost', port=5055): Max retries exceeded with url: /webhook (Caused by NewConnectionError('<urllib3.connection.HTTPConnection object at 0x7f627053beb8>: Failed to establish a new connection: [Errno 111] Connection refused',))
Encountered an exception while running action 'action_get_information'. Bot will continue, but the actions events are lost. Make sure to fix the exception in your custom code.
Failed to run custom action 'action_get_information'. Couldn't connect to the server at 'http://localhost:5055/webhook'. Is the server running? Error: HTTPConnectionPool(host='localhost', port=5055): Max retries exceeded with url: /webhook (Caused by NewConnectionError('<urllib3.connection.HTTPConnection object at 0x7f627048b9e8>: Failed to establish a new connection: [Errno 111] Connection refused',))
Encountered an exception while running action 'action_get_information'. Bot will continue, but the actions events are lost. Make sure to fix the exception in your custom code.
Failed to run custom action 'action_get_information'. Couldn't connect to the server at 'http://localhost:5055/webhook'. Is the server running? Error: HTTPConnectionPool(host='localhost', port=5055): Max retries exceeded with url: /webhook (Caused by NewConnectionError('<urllib3.connection.HTTPConnection object at 0x7f627020e400>: Failed to establish a new connection: [Errno 111] Connection refused',))
Encountered an exception while running action 'action_get_information'. Bot will continue, but the actions events are lost. Make sure to fix the exception in your custom code.
